<?xml version="1.0"?>
<robot name="simple_robot">
  <link name="base_link">
    <inertial>
      <mass value="1.0"/>
      <inertia ixx="0.1" ixy="0.0" ixz="0.0" iyy="0.1" iyz="0.0" izz="0.1"/>
    </inertial>
    <visual>
      <geometry>
        <box size="0.5 0.5 0.5"/>
      </geometry>
      <material name="blue">
        <color rgba="0 0 1 1"/>
      </material>
    </visual>
    <collision>
      <geometry>
        <box size="0.5 0.5 0.5"/>
      </geometry>
    </collision>
  </link>

  <link name="upper_arm">
    <inertial>
      <mass value="0.5"/>
      <inertia ixx="0.05" ixy="0.0" ixz="0.0" iyy="0.05" iyz="0.0" izz="0.05"/>
    </inertial>
    <visual>
      <geometry>
        <cylinder length="0.6" radius="0.05"/>
      </geometry>
      <material name="red">
        <color rgba="1 0 0 1"/>
      </material>
    </visual>
    <collision>
      <geometry>
        <cylinder length="0.6" radius="0.05"/>
      </geometry>
    </collision>
  </link>

  <joint name="torso_to_upper_arm" type="revolute">
    <parent link="base_link"/>
    <child link="upper_arm"/>
    <origin xyz="0 0 0.5" rpy="0 0 0"/>
    <axis xyz="1 0 0"/>
    <limit lower="-1.57" upper="1.57" effort="100" velocity="1"/>
  </joint>
</robot>